Exception in thread Thread-3:
Traceback (most recent call last):
  File "/global/common/software/nersc9/pytorch/2.0.1/lib/python3.9/threading.py", line 980, in _bootstrap_inner
    self.run()
  File "/global/common/software/nersc9/pytorch/2.0.1/lib/python3.9/threading.py", line 917, in run
    self._target(*self._args, **self._kwargs)
  File "/global/common/software/nersc9/pytorch/2.0.1/lib/python3.9/site-packages/torch/utils/data/_utils/pin_memory.py", line 51, in _pin_memory_loop
    do_one_step()
  File "/global/common/software/nersc9/pytorch/2.0.1/lib/python3.9/site-packages/torch/utils/data/_utils/pin_memory.py", line 28, in do_one_step
    r = in_queue.get(timeout=MP_STATUS_CHECK_INTERVAL)
  File "/global/common/software/nersc9/pytorch/2.0.1/lib/python3.9/multiprocessing/queues.py", line 122, in get
    return _ForkingPickler.loads(res)
  File "/global/common/software/nersc9/pytorch/2.0.1/lib/python3.9/site-packages/torch/multiprocessing/reductions.py", line 307, in rebuild_storage_fd
    fd = df.detach()
  File "/global/common/software/nersc9/pytorch/2.0.1/lib/python3.9/multiprocessing/resource_sharer.py", line 57, in detach
    with _resource_sharer.get_connection(self._id) as conn:
  File "/global/common/software/nersc9/pytorch/2.0.1/lib/python3.9/multiprocessing/resource_sharer.py", line 86, in get_connection
    c = Client(address, authkey=process.current_process().authkey)
  File "/global/common/software/nersc9/pytorch/2.0.1/lib/python3.9/multiprocessing/connection.py", line 502, in Client
    c = SocketClient(address)
  File "/global/common/software/nersc9/pytorch/2.0.1/lib/python3.9/multiprocessing/connection.py", line 630, in SocketClient
    s.connect(address)
FileNotFoundError: [Errno 2] No such file or directory