Exception ignored in: <function _MultiProcessingDataLoaderIter.__del__ at 0x14de8256d160>
Traceback (most recent call last):
  File "/global/common/software/nersc9/pytorch/2.0.1/lib/python3.9/site-packages/torch/utils/data/dataloader.py", line 1478, in __del__
    self._shutdown_workers()
  File "/global/common/software/nersc9/pytorch/2.0.1/lib/python3.9/site-packages/torch/utils/data/dataloader.py", line 1442, in _shutdown_workers
    w.join(timeout=_utils.MP_STATUS_CHECK_INTERVAL)
  File "/global/common/software/nersc9/pytorch/2.0.1/lib/python3.9/multiprocessing/process.py", line 149, in join
    res = self._popen.wait(timeout)
  File "/global/common/software/nersc9/pytorch/2.0.1/lib/python3.9/multiprocessing/popen_fork.py", line 40, in wait
    if not wait([self.sentinel], timeout):
  File "/global/common/software/nersc9/pytorch/2.0.1/lib/python3.9/multiprocessing/connection.py", line 931, in wait
    ready = selector.select(timeout)
  File "/global/common/software/nersc9/pytorch/2.0.1/lib/python3.9/selectors.py", line 416, in select
    fd_event_list = self._selector.poll(timeout)
KeyboardInterrupt:
Process SpawnProcess-1:
Traceback (most recent call last):
  File "/global/common/software/nersc9/pytorch/2.0.1/lib/python3.9/multiprocessing/process.py", line 318, in _bootstrap
    util._exit_function()
  File "/global/common/software/nersc9/pytorch/2.0.1/lib/python3.9/multiprocessing/util.py", line 357, in _exit_function
    p.join()
  File "/global/common/software/nersc9/pytorch/2.0.1/lib/python3.9/multiprocessing/process.py", line 149, in join
    res = self._popen.wait(timeout)
  File "/global/common/software/nersc9/pytorch/2.0.1/lib/python3.9/multiprocessing/popen_fork.py", line 43, in wait
    return self.poll(os.WNOHANG if timeout == 0.0 else 0)
  File "/global/common/software/nersc9/pytorch/2.0.1/lib/python3.9/multiprocessing/popen_fork.py", line 27, in poll
    pid, sts = os.waitpid(self.pid, flag)
KeyboardInterrupt